"""Comprehensive edge case tests for CLI error handling system.

Task 251: Test edge cases and boundary conditions for the unified CLI
error handling system, including recovery mechanisms, user interactions,
and complex error scenarios.
"""

import pytest
import tempfile
import os
import subprocess
from pathlib import Path
from unittest.mock import Mock, patch, MagicMock
from typer.testing import CliRunner

# Import error handling components
from wqm_cli.cli.error_handling import (
    ErrorHandler, WqmError, ErrorCategory, ErrorSeverity, ErrorContext,
    RecoveryAction, handle_cli_error, setup_exception_hook
)
from wqm_cli.cli.main import app


class TestErrorHandlerEdgeCases:
    """Test error handler edge cases and boundary conditions."""

    def setup_method(self):
        """Setup test environment."""
        self.error_handler = ErrorHandler()

    def test_error_handler_with_empty_context(self):
        """Test error handling with minimal context information."""
        context = ErrorContext(command="")
        exception = Exception("Empty context test")

        error = self.error_handler._classify_error(exception, context)

        assert error.title == "Unexpected Error"
        assert error.category == ErrorCategory.SYSTEM
        assert error.context.command == ""

    def test_error_handler_with_very_long_error_message(self):
        """Test handling of very long error messages."""
        long_message = "a" * 10000  # Very long error message
        context = ErrorContext(command="test")
        exception = Exception(long_message)

        error = self.error_handler._classify_error(exception, context)

        # Should handle gracefully without truncation issues
        assert error.original_exception.args[0] == long_message
        assert len(error.recovery_actions) > 0

    def test_error_handler_with_unicode_error_messages(self):
        """Test handling of Unicode characters in error messages."""
        unicode_message = "æµ‹è¯•é”™è¯¯: Ã±oÃ±o error with Ã©mojis ðŸš¨"
        context = ErrorContext(command="test")
        exception = Exception(unicode_message)

        error = self.error_handler._classify_error(exception, context)

        assert error.original_exception.args[0] == unicode_message
        assert error.title  # Should not fail with Unicode

    def test_nested_exception_handling(self):
        """Test handling of nested exceptions."""
        inner_exception = ValueError("Inner error")
        outer_exception = RuntimeError("Outer error")
        outer_exception.__cause__ = inner_exception

        context = ErrorContext(command="test")
        error = self.error_handler._classify_error(outer_exception, context)

        assert error.original_exception is outer_exception
        # Should be able to handle nested exception structure

    def test_multiple_simultaneous_error_classifications(self):
        """Test concurrent error classification."""
        import threading
        import time

        errors = []
        context = ErrorContext(command="test")

        def classify_error(i):
            exception = Exception(f"Error {i}")
            error = self.error_handler._classify_error(exception, context)
            errors.append(error)

        threads = []
        for i in range(10):
            thread = threading.Thread(target=classify_error, args=(i,))
            threads.append(thread)
            thread.start()

        for thread in threads:
            thread.join()

        # All errors should be classified successfully
        assert len(errors) == 10
        assert all(error.title for error in errors)

    def test_error_history_thread_safety(self):
        """Test error history management under concurrent access."""
        import threading

        def add_error():
            context = ErrorContext(command="test")
            exception = Exception("Test error")
            error = self.error_handler._classify_error(exception, context)
            self.error_handler.last_errors.append(error)

        threads = []
        for _ in range(20):
            thread = threading.Thread(target=add_error)
            threads.append(thread)
            thread.start()

        for thread in threads:
            thread.join()

        # Should not exceed history limit even with concurrent access
        assert len(self.error_handler.last_errors) <= self.error_handler.error_history_limit

    def test_recovery_action_with_malformed_command(self):
        """Test recovery actions with malformed command strings."""
        recovery_action = RecoveryAction(
            action="test",
            description="Test action",
            command="malformed command with | && special chars",
            auto_applicable=True,
            requires_confirmation=False
        )

        # Should handle malformed commands gracefully
        assert recovery_action.command
        assert recovery_action.auto_applicable

    def test_error_context_with_extreme_values(self):
        """Test error context with extreme or unusual values."""
        # Very long working directory path
        long_path = "/very" + "/long" * 100 + "/path"

        # Large environment dictionary
        large_env = {f"VAR_{i}": f"value_{i}" for i in range(1000)}

        # Many arguments
        many_args = [f"arg_{i}" for i in range(100)]

        context = ErrorContext(
            command="test",
            arguments=many_args,
            working_dir=long_path,
            environment=large_env
        )

        # Should handle extreme values without issues
        assert len(context.arguments) == 100
        assert context.working_dir == long_path
        assert len(context.environment) == 1000

    def test_error_classification_with_complex_stack_trace(self):
        """Test error classification when exception has complex stack trace."""
        try:
            def level_3():
                raise ValueError("Deep error")

            def level_2():
                level_3()

            def level_1():
                level_2()

            level_1()
        except Exception as e:
            context = ErrorContext(command="test")
            error = self.error_handler._classify_error(e, context)

            assert error.original_exception is e
            assert error.category == ErrorCategory.VALIDATION  # ValueError -> validation


class TestErrorHandlerRecoveryMechanisms:
    """Test error recovery mechanisms and user interactions."""

    def setup_method(self):
        """Setup test environment."""
        self.error_handler = ErrorHandler()

    def test_auto_recovery_action_execution(self):
        """Test automatic execution of recovery actions."""
        with patch('subprocess.run') as mock_run:
            mock_run.return_value.returncode = 0
            mock_run.return_value.stdout = "Success"
            mock_run.return_value.stderr = ""

            recovery_action = RecoveryAction(
                action="test",
                description="Test auto action",
                command="echo test",
                auto_applicable=True,
                requires_confirmation=False
            )

            context = ErrorContext(command="test")
            error = WqmError(
                title="Test Error",
                message="Test message",
                category=ErrorCategory.SYSTEM,
                severity=ErrorSeverity.MEDIUM,
                context=context,
                recovery_actions=[recovery_action]
            )

            with patch('wqm_cli.cli.error_handling.console'):
                self.error_handler._suggest_recovery(error)

            # Should have executed the command
            mock_run.assert_called_once()

    def test_recovery_action_timeout_handling(self):
        """Test handling of recovery actions that timeout."""
        with patch('subprocess.run') as mock_run:
            mock_run.side_effect = subprocess.TimeoutExpired("echo", 30)

            recovery_action = RecoveryAction(
                action="test",
                description="Test timeout action",
                command="sleep 100",
                auto_applicable=True,
                requires_confirmation=False
            )

            context = ErrorContext(command="test")
            error = WqmError(
                title="Test Error",
                message="Test message",
                category=ErrorCategory.SYSTEM,
                severity=ErrorSeverity.MEDIUM,
                context=context,
                recovery_actions=[recovery_action]
            )

            with patch('wqm_cli.cli.error_handling.console'):
                # Should handle timeout gracefully
                self.error_handler._suggest_recovery(error)

    def test_recovery_action_permission_error(self):
        """Test recovery actions that fail due to permission errors."""
        with patch('subprocess.run') as mock_run:
            mock_run.side_effect = PermissionError("Permission denied")

            recovery_action = RecoveryAction(
                action="test",
                description="Test permission action",
                command="sudo echo test",
                auto_applicable=True,
                requires_confirmation=False
            )

            context = ErrorContext(command="test")
            error = WqmError(
                title="Test Error",
                message="Test message",
                category=ErrorCategory.SYSTEM,
                severity=ErrorSeverity.MEDIUM,
                context=context,
                recovery_actions=[recovery_action]
            )

            with patch('wqm_cli.cli.error_handling.console'):
                # Should handle permission error gracefully
                self.error_handler._suggest_recovery(error)

    def test_manual_recovery_action_user_cancellation(self):
        """Test manual recovery actions when user cancels."""
        with patch('rich.prompt.Confirm.ask') as mock_confirm:
            # User chooses not to execute actions
            mock_confirm.return_value = False

            recovery_action = RecoveryAction(
                action="test",
                description="Test manual action",
                command="echo test",
                auto_applicable=False,
                requires_confirmation=True
            )

            context = ErrorContext(command="test")
            error = WqmError(
                title="Test Error",
                message="Test message",
                category=ErrorCategory.SYSTEM,
                severity=ErrorSeverity.MEDIUM,
                context=context,
                recovery_actions=[recovery_action]
            )

            with patch('wqm_cli.cli.error_handling.console'):
                self.error_handler._suggest_recovery(error)

            # Should ask for confirmation
            mock_confirm.assert_called()

    def test_multiple_recovery_actions_mixed_types(self):
        """Test handling multiple recovery actions of different types."""
        auto_action = RecoveryAction(
            action="auto",
            description="Auto action",
            command="echo auto",
            auto_applicable=True,
            requires_confirmation=False
        )

        manual_action = RecoveryAction(
            action="manual",
            description="Manual action",
            command="echo manual",
            auto_applicable=False,
            requires_confirmation=True
        )

        no_command_action = RecoveryAction(
            action="no_cmd",
            description="Action without command",
            auto_applicable=True,
            requires_confirmation=False
        )

        context = ErrorContext(command="test")
        error = WqmError(
            title="Test Error",
            message="Test message",
            category=ErrorCategory.SYSTEM,
            severity=ErrorSeverity.MEDIUM,
            context=context,
            recovery_actions=[auto_action, manual_action, no_command_action]
        )

        with patch('subprocess.run') as mock_run:
            mock_run.return_value.returncode = 0
            mock_run.return_value.stdout = "Success"
            mock_run.return_value.stderr = ""

            with patch('rich.prompt.Confirm.ask') as mock_confirm:
                mock_confirm.return_value = False  # User declines manual actions

                with patch('wqm_cli.cli.error_handling.console'):
                    self.error_handler._suggest_recovery(error)

        # Auto action should be executed
        mock_run.assert_called_once_with(["echo", "auto"], capture_output=True, text=True, timeout=30)


class TestErrorHandlerSpecializedErrors:
    """Test handling of specialized error types and scenarios."""

    def setup_method(self):
        """Setup test environment."""
        self.error_handler = ErrorHandler()

    def test_connection_error_with_ipv6_address(self):
        """Test connection errors with IPv6 addresses."""
        context = ErrorContext(command="admin", subcommand="status")
        exception = ConnectionError("Connection to [::1]:6333 refused")

        error = self.error_handler._classify_error(exception, context)

        assert error.category == ErrorCategory.CONNECTION
        assert any("service" in action.description.lower() for action in error.recovery_actions)

    def test_file_not_found_with_network_path(self):
        """Test file not found errors with network paths."""
        context = ErrorContext(command="ingest", arguments=["//remote/share/file.pdf"])
        exception = FileNotFoundError("No such file or directory: //remote/share/file.pdf")

        error = self.error_handler._classify_error(exception, context)

        assert error.category == ErrorCategory.FILE_SYSTEM
        assert "file path" in error.recovery_actions[0].description.lower()

    def test_permission_error_with_specific_file(self):
        """Test permission errors with specific file information."""
        context = ErrorContext(command="config", arguments=["/etc/qdrant/config.yaml"])
        exception = PermissionError("Permission denied: '/etc/qdrant/config.yaml'")

        error = self.error_handler._classify_error(exception, context)

        assert error.category == ErrorCategory.PERMISSION
        assert "/etc/qdrant/config.yaml" in context.arguments[0]

    def test_validation_error_with_structured_data(self):
        """Test validation errors with complex structured error information."""
        class MockValidationError(Exception):
            def __init__(self, message, errors=None):
                super().__init__(message)
                self.errors = errors or []

        validation_errors = [
            {"field": "qdrant.url", "message": "Invalid URL format"},
            {"field": "embedding.model", "message": "Model not found"}
        ]

        context = ErrorContext(command="config", subcommand="validate")
        exception = MockValidationError("Validation failed", validation_errors)

        error = self.error_handler._classify_error(exception, context)

        assert error.category == ErrorCategory.CONFIGURATION
        assert any("validate" in action.description.lower() for action in error.recovery_actions)

    def test_network_timeout_with_retry_logic(self):
        """Test network timeout errors with retry suggestions."""
        context = ErrorContext(command="admin", subcommand="status")
        exception = TimeoutError("Request to http://localhost:6333 timed out after 30 seconds")

        error = self.error_handler._classify_error(exception, context)

        assert error.category == ErrorCategory.NETWORK
        assert any("retry" in action.description.lower() for action in error.recovery_actions)
        assert any("timeout" in action.description.lower() for action in error.recovery_actions)

    def test_disk_space_error_with_specific_location(self):
        """Test disk space errors with specific filesystem information."""
        context = ErrorContext(command="ingest", arguments=["large_file.pdf"])
        exception = OSError("No space left on device")

        error = self.error_handler._classify_error(exception, context)

        assert error.category == ErrorCategory.SYSTEM
        assert error.severity == ErrorSeverity.CRITICAL
        assert any("space" in action.description.lower() for action in error.recovery_actions)

    def test_authentication_error_with_token_expiry(self):
        """Test authentication errors with token expiry information."""
        context = ErrorContext(command="admin", subcommand="status")
        exception = Exception("Authentication failed: Token expired at 2023-12-25T10:00:00Z")

        # Should classify as authentication error due to keyword matching
        error = self.error_handler._classify_error(exception, context)

        assert error.category == ErrorCategory.AUTHENTICATION
        assert any("api" in action.description.lower() for action in error.recovery_actions)


class TestCLIErrorIntegration:
    """Test CLI error handling integration with actual CLI commands."""

    def setup_method(self):
        """Setup test environment."""
        self.runner = CliRunner()

    def test_cli_exception_hook_installation(self):
        """Test that exception hook is properly installed."""
        with patch('sys.excepthook') as mock_hook:
            setup_exception_hook()
            # Should have modified the exception hook
            assert mock_hook != None  # Just checking it was accessed

    def test_keyboard_interrupt_handling(self):
        """Test that KeyboardInterrupt is handled gracefully."""
        # This is difficult to test directly, but we can verify the handler exists
        original_hook = __import__('sys').excepthook

        setup_exception_hook()
        new_hook = __import__('sys').excepthook

        # Hook should be different after setup
        assert new_hook != original_hook

    def test_error_context_creation_from_cli_args(self):
        """Test error context creation from CLI arguments."""
        args = ["config", "set", "qdrant.url", "http://localhost:6333"]

        context = ErrorContext(
            command="config",
            subcommand="set",
            arguments=["qdrant.url", "http://localhost:6333"],
            flags={"verbose": True}
        )

        assert context.command == "config"
        assert context.subcommand == "set"
        assert context.arguments == ["qdrant.url", "http://localhost:6333"]
        assert context.flags["verbose"] is True

    def test_error_handling_with_debug_mode(self):
        """Test error handling behavior in debug mode vs normal mode."""
        with patch('wqm_cli.cli.error_handling.handle_cli_error') as mock_handler:
            # This would be called by the CLI error handling system
            exception = Exception("Test error")
            context = ErrorContext(command="test")

            handle_cli_error(exception, context, show_traceback=True)
            mock_handler.assert_called_once_with(exception, context, show_traceback=True)

    def test_error_recovery_with_actual_commands(self):
        """Test error recovery suggestions for real CLI commands."""
        error_handler = ErrorHandler()

        # Test service connection error
        context = ErrorContext(command="admin", subcommand="status")
        exception = ConnectionRefusedError("Connection refused")

        error = error_handler._classify_error(exception, context)

        # Should suggest checking service status
        action_commands = [action.command for action in error.recovery_actions if action.command]
        assert any("service" in cmd for cmd in action_commands)

    def test_error_message_formatting_edge_cases(self):
        """Test error message formatting with edge cases."""
        with patch('wqm_cli.cli.error_handling.console') as mock_console:
            error_handler = ErrorHandler()
            context = ErrorContext(command="test")

            # Error with no message
            exception = Exception()
            error = error_handler._classify_error(exception, context)
            error_handler._display_error(error)

            # Should not fail with empty message
            mock_console.print.assert_called()


if __name__ == "__main__":
    pytest.main([__file__, "-v"])