"""
Comprehensive Unit Tests for CLI Error Handling System

Tests advanced error handling, recovery mechanisms, and edge cases
for malformed input, conflicting options, and failure scenarios.

Task 251: Comprehensive testing for unified CLI interface error handling.
"""

import pytest
import subprocess
import sys
import os
from pathlib import Path
from unittest.mock import Mock, patch, call, MagicMock
from contextlib import contextmanager

# Add src paths for imports
sys.path.insert(0, str(Path(__file__).parent.parent.parent / "src" / "python"))

# Set CLI mode before any imports
os.environ["WQM_CLI_MODE"] = "true"
os.environ["WQM_LOG_INIT"] = "false"

try:
    from wqm_cli.cli.error_handling import (
        ErrorHandler,
        ErrorSeverity,
        ErrorCategory,
        ErrorContext,
        RecoveryAction,
        WqmError,
        error_handler,
        handle_cli_error,
        setup_exception_hook
    )
    ERROR_HANDLING_AVAILABLE = True
except ImportError as e:
    ERROR_HANDLING_AVAILABLE = False
    print(f"Warning: error_handling module not available: {e}")


@pytest.mark.skipif(not ERROR_HANDLING_AVAILABLE, reason="Error handling module not available")
class TestErrorContext:
    """Test ErrorContext dataclass functionality."""

    def test_error_context_initialization(self):
        """Test ErrorContext initializes with correct defaults."""
        context = ErrorContext(command="test")

        assert context.command == "test"
        assert context.subcommand is None
        assert context.arguments == []
        assert context.flags == {}
        assert context.working_dir is not None
        assert context.environment is not None
        assert isinstance(context.environment, dict)

    def test_error_context_full_initialization(self):
        """Test ErrorContext with all parameters."""
        context = ErrorContext(
            command="wqm",
            subcommand="memory",
            arguments=["add", "rule"],
            flags={"verbose": True, "force": False},
            working_dir="/tmp",
            config_file="/path/config.yaml",
            environment={"TEST": "value"}
        )

        assert context.command == "wqm"
        assert context.subcommand == "memory"
        assert context.arguments == ["add", "rule"]
        assert context.flags == {"verbose": True, "force": False}
        assert context.working_dir == "/tmp"
        assert context.config_file == "/path/config.yaml"
        assert context.environment == {"TEST": "value"}

    def test_error_context_empty_arguments(self):
        """Test ErrorContext handles None arguments correctly."""
        context = ErrorContext(command="test", arguments=None)
        assert context.arguments == []

    def test_error_context_empty_flags(self):
        """Test ErrorContext handles None flags correctly."""
        context = ErrorContext(command="test", flags=None)
        assert context.flags == {}


@pytest.mark.skipif(not ERROR_HANDLING_AVAILABLE, reason="Error handling module not available")
class TestRecoveryAction:
    """Test RecoveryAction dataclass functionality."""

    def test_recovery_action_basic(self):
        """Test basic RecoveryAction creation."""
        action = RecoveryAction(
            action="test_action",
            description="Test description"
        )

        assert action.action == "test_action"
        assert action.description == "Test description"
        assert action.command is None
        assert action.auto_applicable is False
        assert action.requires_confirmation is True

    def test_recovery_action_full(self):
        """Test full RecoveryAction creation."""
        action = RecoveryAction(
            action="restart_service",
            description="Restart the service",
            command="wqm service restart",
            auto_applicable=True,
            requires_confirmation=False
        )

        assert action.action == "restart_service"
        assert action.description == "Restart the service"
        assert action.command == "wqm service restart"
        assert action.auto_applicable is True
        assert action.requires_confirmation is False


@pytest.mark.skipif(not ERROR_HANDLING_AVAILABLE, reason="Error handling module not available")
class TestWqmError:
    """Test WqmError dataclass functionality."""

    def test_wqm_error_basic(self):
        """Test basic WqmError creation."""
        context = ErrorContext(command="test")
        error = WqmError(
            title="Test Error",
            message="Test message",
            category=ErrorCategory.SYSTEM,
            severity=ErrorSeverity.LOW,
            context=context
        )

        assert error.title == "Test Error"
        assert error.message == "Test message"
        assert error.category == ErrorCategory.SYSTEM
        assert error.severity == ErrorSeverity.LOW
        assert error.context == context
        assert error.original_exception is None
        assert error.recovery_actions == []
        assert error.related_commands == []
        assert error.documentation_links == []

    def test_wqm_error_full(self):
        """Test full WqmError creation."""
        context = ErrorContext(command="test")
        exception = ValueError("test error")
        recovery_actions = [RecoveryAction("test", "Test action")]
        related_commands = ["admin", "config"]
        doc_links = ["https://example.com/docs"]

        error = WqmError(
            title="Full Error",
            message="Full message",
            category=ErrorCategory.CONFIGURATION,
            severity=ErrorSeverity.HIGH,
            context=context,
            original_exception=exception,
            recovery_actions=recovery_actions,
            related_commands=related_commands,
            documentation_links=doc_links
        )

        assert error.title == "Full Error"
        assert error.original_exception == exception
        assert error.recovery_actions == recovery_actions
        assert error.related_commands == related_commands
        assert error.documentation_links == doc_links


@pytest.mark.skipif(not ERROR_HANDLING_AVAILABLE, reason="Error handling module not available")
class TestErrorHandler:
    """Test ErrorHandler core functionality."""

    @pytest.fixture
    def handler(self):
        """Create a fresh error handler instance."""
        return ErrorHandler()

    @pytest.fixture
    def sample_context(self):
        """Create sample error context."""
        return ErrorContext(
            command="wqm",
            subcommand="test",
            arguments=["arg1"],
            flags={"verbose": True}
        )

    def test_error_handler_initialization(self, handler):
        """Test ErrorHandler initializes correctly."""
        assert handler is not None
        assert hasattr(handler, 'error_patterns')
        assert hasattr(handler, 'recovery_strategies')
        assert hasattr(handler, 'last_errors')
        assert len(handler.error_patterns) > 0
        assert len(handler.recovery_strategies) > 0
        assert handler.last_errors == []
        assert handler.error_history_limit == 10

    def test_connection_refused_classification(self, handler, sample_context):
        """Test connection refused error classification."""
        exception = ConnectionRefusedError("Connection refused")

        with patch.object(handler, '_display_error'), patch.object(handler, '_suggest_recovery'):
            error = handler.handle_exception(exception, sample_context)

        assert error.category == ErrorCategory.CONNECTION
        assert error.severity == ErrorSeverity.HIGH
        assert "connection" in error.title.lower()
        assert len(error.recovery_actions) > 0

    def test_file_not_found_classification(self, handler, sample_context):
        """Test file not found error classification."""
        exception = FileNotFoundError("No such file or directory")

        with patch.object(handler, '_display_error'), patch.object(handler, '_suggest_recovery'):
            error = handler.handle_exception(exception, sample_context)

        assert error.category == ErrorCategory.FILE_SYSTEM
        assert error.severity == ErrorSeverity.MEDIUM
        assert "file" in error.title.lower()

    def test_permission_denied_classification(self, handler, sample_context):
        """Test permission denied error classification."""
        exception = PermissionError("Permission denied")

        with patch.object(handler, '_display_error'), patch.object(handler, '_suggest_recovery'):
            error = handler.handle_exception(exception, sample_context)

        assert error.category == ErrorCategory.PERMISSION
        assert error.severity == ErrorSeverity.HIGH
        assert "permission" in error.title.lower()

    def test_authentication_failed_classification(self, handler, sample_context):
        """Test authentication error classification."""
        exception = Exception("Authentication failed")

        with patch.object(handler, '_display_error'), patch.object(handler, '_suggest_recovery'):
            error = handler.handle_exception(exception, sample_context)

        assert error.category == ErrorCategory.AUTHENTICATION
        assert error.severity == ErrorSeverity.HIGH

    def test_timeout_classification(self, handler, sample_context):
        """Test timeout error classification."""
        exception = TimeoutError("Operation timed out")

        with patch.object(handler, '_display_error'), patch.object(handler, '_suggest_recovery'):
            error = handler.handle_exception(exception, sample_context)

        assert error.category == ErrorCategory.NETWORK
        assert error.severity == ErrorSeverity.MEDIUM
        assert "timeout" in error.title.lower()

    def test_disk_space_classification(self, handler, sample_context):
        """Test disk space error classification."""
        exception = OSError("No space left on device")

        with patch.object(handler, '_display_error'), patch.object(handler, '_suggest_recovery'):
            error = handler.handle_exception(exception, sample_context)

        assert error.category == ErrorCategory.SYSTEM
        assert error.severity == ErrorSeverity.CRITICAL

    def test_generic_error_classification(self, handler, sample_context):
        """Test generic error classification."""
        exception = RuntimeError("Unknown runtime error")

        with patch.object(handler, '_display_error'), patch.object(handler, '_suggest_recovery'):
            error = handler.handle_exception(exception, sample_context)

        assert error.category == ErrorCategory.SYSTEM
        assert error.severity == ErrorSeverity.MEDIUM
        assert "unexpected" in error.title.lower()

    def test_error_history_tracking(self, handler, sample_context):
        """Test error history is tracked correctly."""
        exception1 = ValueError("Error 1")
        exception2 = ValueError("Error 2")

        with patch.object(handler, '_display_error'), patch.object(handler, '_suggest_recovery'):
            handler.handle_exception(exception1, sample_context)
            handler.handle_exception(exception2, sample_context)

        assert len(handler.last_errors) == 2
        assert handler.last_errors[0].original_exception == exception1
        assert handler.last_errors[1].original_exception == exception2

    def test_error_history_limit(self, handler, sample_context):
        """Test error history respects limit."""
        # Set a small limit for testing
        handler.error_history_limit = 3

        with patch.object(handler, '_display_error'), patch.object(handler, '_suggest_recovery'):
            for i in range(5):
                exception = ValueError(f"Error {i}")
                handler.handle_exception(exception, sample_context)

        assert len(handler.last_errors) == 3
        # Should keep the most recent errors
        assert "Error 4" in str(handler.last_errors[-1].original_exception)

    def test_get_error_history(self, handler, sample_context):
        """Test getting error history."""
        exception = ValueError("Test error")

        with patch.object(handler, '_display_error'), patch.object(handler, '_suggest_recovery'):
            handler.handle_exception(exception, sample_context)

        history = handler.get_error_history()
        assert len(history) == 1
        assert history[0].original_exception == exception
        # Should be a copy, not the original
        assert history is not handler.last_errors

    def test_clear_error_history(self, handler, sample_context):
        """Test clearing error history."""
        exception = ValueError("Test error")

        with patch.object(handler, '_display_error'), patch.object(handler, '_suggest_recovery'):
            handler.handle_exception(exception, sample_context)

        assert len(handler.last_errors) == 1
        handler.clear_error_history()
        assert len(handler.last_errors) == 0

    @patch('wqm_cli.cli.error_handling.console.print')
    def test_display_error_basic(self, mock_print, handler, sample_context):
        """Test basic error display."""
        error = WqmError(
            title="Test Error",
            message="Test message",
            category=ErrorCategory.SYSTEM,
            severity=ErrorSeverity.LOW,
            context=sample_context
        )

        handler._display_error(error)

        assert mock_print.call_count >= 2  # Panel and spacing
        # Check that error information is displayed
        all_calls = [str(call) for call in mock_print.call_args_list]
        combined_output = " ".join(all_calls)
        assert "Test Error" in combined_output

    @patch('wqm_cli.cli.error_handling.console.print')
    def test_display_error_with_traceback(self, mock_print, handler, sample_context):
        """Test error display with traceback."""
        exception = ValueError("Test error")
        error = WqmError(
            title="Test Error",
            message="Test message",
            category=ErrorCategory.SYSTEM,
            severity=ErrorSeverity.LOW,
            context=sample_context,
            original_exception=exception
        )

        handler._display_error(error, show_traceback=True)

        assert mock_print.call_count >= 2
        all_calls = [str(call) for call in mock_print.call_args_list]
        combined_output = " ".join(all_calls)
        assert "Stack trace" in combined_output

    @patch('subprocess.run')
    @patch('wqm_cli.cli.error_handling.console.print')
    def test_suggest_recovery_auto_actions(self, mock_print, mock_run, handler):
        """Test automatic recovery actions execution."""
        mock_run.return_value = subprocess.CompletedProcess(
            args=[], returncode=0, stdout="Success", stderr=""
        )

        recovery_actions = [
            RecoveryAction(
                "check_status",
                "Check status",
                "wqm admin status",
                auto_applicable=True,
                requires_confirmation=False
            )
        ]

        context = ErrorContext(command="test")
        error = WqmError(
            title="Test Error",
            message="Test message",
            category=ErrorCategory.SYSTEM,
            severity=ErrorSeverity.LOW,
            context=context,
            recovery_actions=recovery_actions
        )

        handler._suggest_recovery(error)

        mock_run.assert_called_once()
        assert mock_print.call_count >= 2

    @patch('wqm_cli.cli.error_handling.Confirm.ask', return_value=False)
    @patch('wqm_cli.cli.error_handling.console.print')
    def test_suggest_recovery_manual_actions_declined(self, mock_print, mock_confirm, handler):
        """Test manual recovery actions when user declines."""
        recovery_actions = [
            RecoveryAction(
                "manual_action",
                "Manual action",
                "wqm test command",
                requires_confirmation=True
            )
        ]

        context = ErrorContext(command="test")
        error = WqmError(
            title="Test Error",
            message="Test message",
            category=ErrorCategory.SYSTEM,
            severity=ErrorSeverity.LOW,
            context=context,
            recovery_actions=recovery_actions
        )

        handler._suggest_recovery(error)

        mock_confirm.assert_called_once()
        assert mock_print.call_count >= 1

    def test_error_context_manager(self, handler):
        """Test error context manager."""
        with pytest.raises(SystemExit):  # typer.Exit raises SystemExit
            with handler.error_context("test_command", subcommand="sub"):
                raise ValueError("Test error")

    def test_error_context_manager_success(self, handler):
        """Test error context manager with successful operation."""
        with handler.error_context("test_command") as context:
            assert context.command == "test_command"
            # No exception raised


@pytest.mark.skipif(not ERROR_HANDLING_AVAILABLE, reason="Error handling module not available")
class TestErrorHandlingEdgeCases:
    """Test edge cases and error conditions."""

    @pytest.fixture
    def handler(self):
        """Create a fresh error handler instance."""
        return ErrorHandler()

    @pytest.fixture
    def sample_context(self):
        """Create sample error context."""
        return ErrorContext(command="test")

    def test_empty_exception_message(self, handler, sample_context):
        """Test handling exception with empty message."""
        exception = ValueError("")

        with patch.object(handler, '_display_error'), patch.object(handler, '_suggest_recovery'):
            error = handler.handle_exception(exception, sample_context)

        assert error is not None
        assert error.original_exception == exception

    def test_none_exception_message(self, handler, sample_context):
        """Test handling exception with None message."""
        exception = Exception()
        exception.args = ()  # No message

        with patch.object(handler, '_display_error'), patch.object(handler, '_suggest_recovery'):
            error = handler.handle_exception(exception, sample_context)

        assert error is not None

    def test_unicode_in_exception_message(self, handler, sample_context):
        """Test handling exception with unicode characters."""
        exception = ValueError("Unicode error: 🚨 測試 ñoño")

        with patch.object(handler, '_display_error'), patch.object(handler, '_suggest_recovery'):
            error = handler.handle_exception(exception, sample_context)

        assert error is not None
        assert "Unicode error" in str(error.original_exception)

    def test_very_long_exception_message(self, handler, sample_context):
        """Test handling exception with very long message."""
        long_message = "A" * 10000
        exception = ValueError(long_message)

        with patch.object(handler, '_display_error'), patch.object(handler, '_suggest_recovery'):
            error = handler.handle_exception(exception, sample_context)

        assert error is not None
        assert len(str(error.original_exception)) > 1000

    def test_nested_exception(self, handler, sample_context):
        """Test handling nested/chained exceptions."""
        try:
            try:
                raise ValueError("Inner error")
            except ValueError as e:
                raise ConnectionError("Outer error") from e
        except ConnectionError as exception:
            with patch.object(handler, '_display_error'), patch.object(handler, '_suggest_recovery'):
                error = handler.handle_exception(exception, sample_context)

        assert error is not None
        assert "connection" in error.title.lower()

    @patch('subprocess.run', side_effect=subprocess.TimeoutExpired("cmd", 30))
    @patch('wqm_cli.cli.error_handling.console.print')
    def test_recovery_action_timeout(self, mock_print, mock_run, handler):
        """Test recovery action that times out."""
        recovery_actions = [
            RecoveryAction(
                "timeout_action",
                "Action that times out",
                "wqm long-running-command",
                auto_applicable=True,
                requires_confirmation=False
            )
        ]

        context = ErrorContext(command="test")
        error = WqmError(
            title="Test Error",
            message="Test message",
            category=ErrorCategory.SYSTEM,
            severity=ErrorSeverity.LOW,
            context=context,
            recovery_actions=recovery_actions
        )

        handler._suggest_recovery(error)

        mock_run.assert_called_once()
        all_calls = [str(call) for call in mock_print.call_args_list]
        combined_output = " ".join(all_calls)
        assert "Timeout" in combined_output

    @patch('subprocess.run', side_effect=Exception("Command failed"))
    @patch('wqm_cli.cli.error_handling.console.print')
    def test_recovery_action_execution_error(self, mock_print, mock_run, handler):
        """Test recovery action that fails to execute."""
        recovery_actions = [
            RecoveryAction(
                "failing_action",
                "Action that fails",
                "wqm failing-command",
                auto_applicable=True,
                requires_confirmation=False
            )
        ]

        context = ErrorContext(command="test")
        error = WqmError(
            title="Test Error",
            message="Test message",
            category=ErrorCategory.SYSTEM,
            severity=ErrorSeverity.LOW,
            context=context,
            recovery_actions=recovery_actions
        )

        handler._suggest_recovery(error)

        mock_run.assert_called_once()
        all_calls = [str(call) for call in mock_print.call_args_list]
        combined_output = " ".join(all_calls)
        assert "Command failed" in combined_output

    @patch('subprocess.run')
    def test_recovery_action_nonzero_exit(self, mock_run, handler):
        """Test recovery action that exits with non-zero code."""
        mock_run.return_value = subprocess.CompletedProcess(
            args=[], returncode=1, stdout="", stderr="Command error"
        )

        recovery_actions = [
            RecoveryAction(
                "failing_action",
                "Action that fails",
                "wqm failing-command",
                auto_applicable=True,
                requires_confirmation=False
            )
        ]

        context = ErrorContext(command="test")
        error = WqmError(
            title="Test Error",
            message="Test message",
            category=ErrorCategory.SYSTEM,
            severity=ErrorSeverity.LOW,
            context=context,
            recovery_actions=recovery_actions
        )

        with patch('wqm_cli.cli.error_handling.console.print') as mock_print:
            handler._suggest_recovery(error)

        all_calls = [str(call) for call in mock_print.call_args_list]
        combined_output = " ".join(all_calls)
        assert "Failed" in combined_output

    def test_malformed_error_context(self, handler):
        """Test handling malformed error context."""
        # Context with problematic values
        context = ErrorContext(
            command="",  # Empty command
            arguments=None,  # Will be converted to []
            flags=None,     # Will be converted to {}
            working_dir="",  # Empty working dir
        )

        exception = ValueError("Test error")

        with patch.object(handler, '_display_error'), patch.object(handler, '_suggest_recovery'):
            error = handler.handle_exception(exception, context)

        assert error is not None
        assert error.context.arguments == []
        assert error.context.flags == {}

    @patch('wqm_cli.cli.error_handling.console.print', side_effect=Exception("Print error"))
    def test_display_error_print_failure(self, mock_print, handler):
        """Test handling when display error itself fails."""
        context = ErrorContext(command="test")
        error = WqmError(
            title="Test Error",
            message="Test message",
            category=ErrorCategory.SYSTEM,
            severity=ErrorSeverity.LOW,
            context=context
        )

        # Should not raise exception even if printing fails
        try:
            handler._display_error(error)
        except Exception as e:
            # Should be the mocked print error, not an internal error
            assert "Print error" in str(e)

    def test_recovery_strategies_completeness(self, handler):
        """Test that all error categories have recovery strategies."""
        # Not all categories need strategies, but common ones should
        important_categories = [
            ErrorCategory.CONNECTION,
            ErrorCategory.CONFIGURATION,
            ErrorCategory.FILE_SYSTEM,
            ErrorCategory.SERVICE
        ]

        for category in important_categories:
            assert category in handler.recovery_strategies
            assert len(handler.recovery_strategies[category]) > 0

    def test_error_patterns_completeness(self, handler):
        """Test that error patterns cover common cases."""
        important_patterns = [
            "connection_refused",
            "file_not_found",
            "permission_denied",
            "config_invalid"
        ]

        for pattern in important_patterns:
            assert pattern in handler.error_patterns
            assert callable(handler.error_patterns[pattern])


@pytest.mark.skipif(not ERROR_HANDLING_AVAILABLE, reason="Error handling module not available")
class TestGlobalErrorHandling:
    """Test global error handling functions and setup."""

    def test_global_error_handler_instance(self):
        """Test global error handler instance exists."""
        assert error_handler is not None
        assert isinstance(error_handler, ErrorHandler)

    def test_handle_cli_error_function(self):
        """Test handle_cli_error convenience function."""
        exception = ValueError("Test error")

        with patch.object(error_handler, 'handle_exception') as mock_handle:
            handle_cli_error(exception)

        mock_handle.assert_called_once()
        args, kwargs = mock_handle.call_args
        assert args[0] == exception
        assert isinstance(args[1], ErrorContext)

    def test_handle_cli_error_with_context(self):
        """Test handle_cli_error with provided context."""
        exception = ValueError("Test error")
        context = ErrorContext(command="test")

        with patch.object(error_handler, 'handle_exception') as mock_handle:
            handle_cli_error(exception, context)

        mock_handle.assert_called_once()
        args, kwargs = mock_handle.call_args
        assert args[0] == exception
        assert args[1] == context

    def test_setup_exception_hook(self):
        """Test exception hook setup."""
        original_hook = sys.excepthook

        try:
            setup_exception_hook()
            # Hook should be changed
            assert sys.excepthook != original_hook
        finally:
            # Restore original hook
            sys.excepthook = original_hook

    @patch('sys.exit')
    @patch('wqm_cli.cli.error_handling.console.print')
    def test_exception_hook_keyboard_interrupt(self, mock_print, mock_exit):
        """Test exception hook handles KeyboardInterrupt."""
        setup_exception_hook()

        try:
            # Simulate KeyboardInterrupt
            sys.excepthook(KeyboardInterrupt, KeyboardInterrupt(), None)
        except SystemExit:
            pass

        mock_print.assert_called_once()
        mock_exit.assert_called_once_with(1)

    def test_exception_hook_typer_exit(self):
        """Test exception hook lets typer.Exit through."""
        import typer

        original_hook = sys.excepthook
        setup_exception_hook()

        # Should call original hook for typer.Exit
        with patch.object(sys, 'excepthook', wraps=sys.excepthook) as mock_hook:
            with pytest.raises(SystemExit):
                raise typer.Exit()


if __name__ == "__main__":
    pytest.main([__file__, "-v", "--tb=short"])